<mujoco model="bittle_like_v0">
  <compiler angle="radian" coordinate="local"/>

  <option timestep="0.002" gravity="0 0 -9.81" integrator="RK4"/>

  <default>
    <joint damping="0.18" armature="0.008" limited="true"/>
    <geom friction="1.1 0.08 0.01" rgba="0.62 0.68 0.72 1"/>
    <position kp="12" ctrllimited="true" forcelimited="true" forcerange="-3.5 3.5"/>
  </default>

  <asset>
    <texture name="grid" type="2d" builtin="checker" width="512" height="512"
             rgb1="0.22 0.25 0.25" rgb2="0.36 0.4 0.4"/>
    <material name="grid" texture="grid" texrepeat="4 4"/>
    <material name="body_black" rgba="0.08 0.09 0.1 1"/>
    <material name="body_yellow" rgba="0.95 0.7 0.12 1"/>
    <material name="leg_dark" rgba="0.12 0.12 0.13 1"/>
  </asset>

  <worldbody>
    <light pos="0 0 2" dir="0 0 -1"/>
    <geom name="floor" type="plane" size="5 5 0.05" material="grid"/>

    <body name="torso" pos="0 0 0.20">
      <freejoint name="root"/>
      <geom name="torso_geom" type="box" size="0.115 0.045 0.035" mass="0.34" material="body_black"/>
      <geom name="top_shell" type="box" pos="0.005 0 0.035" size="0.09 0.04 0.012" mass="0.08" material="body_yellow"/>
      <geom name="front_face" type="box" pos="0.125 0 0.01" size="0.018 0.04 0.028" mass="0.03" material="body_yellow"/>

      <body name="front_left_thigh" pos="0.075 0.052 0">
        <joint name="front_left_hip" type="hinge" axis="0 1 0" range="-0.85 0.85"/>
        <geom type="capsule" fromto="0 0 0 0.005 0 -0.078" size="0.012" mass="0.026" material="leg_dark"/>
        <body name="front_left_calf" pos="0.005 0 -0.078">
          <joint name="front_left_knee" type="hinge" axis="0 1 0" range="-1.35 0.15"/>
          <geom type="capsule" fromto="0 0 0 -0.005 0 -0.082" size="0.011" mass="0.022" material="leg_dark"/>
          <geom name="front_left_foot" type="sphere" pos="-0.005 0 -0.092" size="0.017" mass="0.018" rgba="0.04 0.04 0.04 1"/>
        </body>
      </body>

      <body name="front_right_thigh" pos="0.075 -0.052 0">
        <joint name="front_right_hip" type="hinge" axis="0 1 0" range="-0.85 0.85"/>
        <geom type="capsule" fromto="0 0 0 0.005 0 -0.078" size="0.012" mass="0.026" material="leg_dark"/>
        <body name="front_right_calf" pos="0.005 0 -0.078">
          <joint name="front_right_knee" type="hinge" axis="0 1 0" range="-1.35 0.15"/>
          <geom type="capsule" fromto="0 0 0 -0.005 0 -0.082" size="0.011" mass="0.022" material="leg_dark"/>
          <geom name="front_right_foot" type="sphere" pos="-0.005 0 -0.092" size="0.017" mass="0.018" rgba="0.04 0.04 0.04 1"/>
        </body>
      </body>

      <body name="rear_left_thigh" pos="-0.075 0.052 0">
        <joint name="rear_left_hip" type="hinge" axis="0 1 0" range="-0.85 0.85"/>
        <geom type="capsule" fromto="0 0 0 -0.005 0 -0.078" size="0.012" mass="0.026" material="leg_dark"/>
        <body name="rear_left_calf" pos="-0.005 0 -0.078">
          <joint name="rear_left_knee" type="hinge" axis="0 1 0" range="-1.35 0.15"/>
          <geom type="capsule" fromto="0 0 0 0.005 0 -0.082" size="0.011" mass="0.022" material="leg_dark"/>
          <geom name="rear_left_foot" type="sphere" pos="0.005 0 -0.092" size="0.017" mass="0.018" rgba="0.04 0.04 0.04 1"/>
        </body>
      </body>

      <body name="rear_right_thigh" pos="-0.075 -0.052 0">
        <joint name="rear_right_hip" type="hinge" axis="0 1 0" range="-0.85 0.85"/>
        <geom type="capsule" fromto="0 0 0 -0.005 0 -0.078" size="0.012" mass="0.026" material="leg_dark"/>
        <body name="rear_right_calf" pos="-0.005 0 -0.078">
          <joint name="rear_right_knee" type="hinge" axis="0 1 0" range="-1.35 0.15"/>
          <geom type="capsule" fromto="0 0 0 0.005 0 -0.082" size="0.011" mass="0.022" material="leg_dark"/>
          <geom name="rear_right_foot" type="sphere" pos="0.005 0 -0.092" size="0.017" mass="0.018" rgba="0.04 0.04 0.04 1"/>
        </body>
      </body>
    </body>
  </worldbody>

  <actuator>
    <position name="front_left_hip_pos" joint="front_left_hip" ctrlrange="-0.75 0.75"/>
    <position name="front_left_knee_pos" joint="front_left_knee" ctrlrange="-1.25 0.05"/>
    <position name="front_right_hip_pos" joint="front_right_hip" ctrlrange="-0.75 0.75"/>
    <position name="front_right_knee_pos" joint="front_right_knee" ctrlrange="-1.25 0.05"/>
    <position name="rear_left_hip_pos" joint="rear_left_hip" ctrlrange="-0.75 0.75"/>
    <position name="rear_left_knee_pos" joint="rear_left_knee" ctrlrange="-1.25 0.05"/>
    <position name="rear_right_hip_pos" joint="rear_right_hip" ctrlrange="-0.75 0.75"/>
    <position name="rear_right_knee_pos" joint="rear_right_knee" ctrlrange="-1.25 0.05"/>
  </actuator>
</mujoco>
